Workbook

Sheet 1
A1: Capitolo 1 Introduzione
A3: 1.1. I forwards a 1 anno sono contratti in cui una parte ha
A4: (a) il diritto di comprare il sottostante, tra un anno, a un prezzo prefissato;
A5: (b) l’obbligo di comprare il sottostante, tra un anno, a un prezzo prefissato;
A6: (c) l’obbligo di comprare il sottostante, entro un anno, a un prezzo prefissato;
A7: (d) l’obbligo di comprare il sottostante, tra un anno, al prezzo di mercato.
A9: (b)
A10: I forwards a 1 anno sono contratti in cui una parte si impegna a comprare e l’altra a vendere il sottostante, tra 1 anno, a un prezzo prefissato.
A11: Invece, le opzioni sono contratti in cui una delle due parti acquista il diritto di comprare o vendere il sottostante.
A13: 1.2. Solo una delle seguenti affermazioni non è corretta. Quale?
A14: (a) Quando alla CBOE viene esercitata un’opzione sull’IBM, l’IBM emette nuove azioni.
A15: (b) Le opzioni americane possono essere esercitate in qualsiasi momento della loro vita.
... A31: (a)
A33: c | B33: 3
A34: p | B34: 4
A35: K | B35: 30
A36: N_calls | B36: 2
A37: N_puts | B37: 1
A39: ST | B39: =B35+(B36*B33+B37*B34)/B36 -> 35
A41: 1.4. Una call ad 1 anno, con prezzo d’esercizio di $30, costa $3. Una put ad 1 anno, con prezzo d’esercizio di $30, scritta sulla stessa azione costa $4. Supponete che un trader acquisti 2 calls e 1 put.
A42: Qual è il prezzo “soglia” al di sotto del quale il trader consegue un profitto?
A43: (a) $25
A44: (b) $28
A45: (c) $26
A46: (d) $20
A48: (d)
A50: c | B50: 3
A51: p | B51: 4
A52: K | B52: 30
A53: N_calls | B53: 2
A54: N_puts | B54: 1
A56: ST | B56: =B52-(B53*B50+B54*B51)/B54 -> 20
A58: 1.5. Considerate le dimensioni dei mercati dei derivati alla fine di dicembre del 2025, misurate in termini di valori nozionali dei contratti OTC e di valori delle attività sottostanti i derivati di borsa. Solo una delle seguenti affermazioni è corretta, in prima approssimazione. Quale?
A59: (a) Il mercato di borsa è pari al doppio di quello OTC.
A60: (b) Il mercato OTC è pari al doppio di quello di borsa.
A61: (c) Il mercato di borsa è pari a otto volte quello OTC.
A62: (d) Il mercato OTC è pari a otto volte quello di borsa.
A64: (d)
A66: In base ai dati riportati nel Libro, alla fine di dicembre del 2025 le dimensioni del mercato OTC e del mercato di borsa erano pari, rispettivamente, a $844.578 miliardi e a $107.113 miliardi.
A67: Il rapporto tra le due dimensioni è pari a 7,88 (= $844.578 / $107.113). Pertanto, in prima approssimazione, il mercato OTC è pari a otto volte quello di borsa. La risposta corretta è quella sub (d).
...

Sheet 2
A1: Capitolo 2 Mercati dei Futures e Controparti Centralizzate
A3: 2.1. Solo una delle seguenti affermazioni è corretta. Quale?
A4: (a) Sia i forwards sia i futures sono negoziati in borsa.
A5: (b) I forwards sono negoziati in borsa ma i futures no.
A6: (c) I futures sono negoziati in borsa ma i forwards no.
A7: (d) Né i forwards né i futures sono negoziati in borsa.
A9: (c)
A11: I futures vengono trattati solo in borsa. I forwards vengono trattati solo nei mercati OTC.
A13: 2.2. Solo una delle seguenti affermazioni non è corretta. Quale?
A14: (a) I contratti futures durano quasi sempre più dei forward.
A15: (b) I contratti futures sono standardizzati, i contratti forward no.
A16: (c) I contratti forward si concludono con la consegna o con la liquidazione per contanti; in genere, ciò non è vero per i contratti futures.
... A45: Il prezzo futures corrente è pari a ¢70. Ci sarà quindi una richiesta di integrazione dei margini se il prezzo futures supera i ¢72.
A47: Posizione | B47: -1
A48: Dimensione | B48: 50000
A49: F0 | B49: 0.7
A50: Margine iniziale | B50: 4000
A51: Margine di mantenimento | C51: 3000
A53: St | B53: =B49+(B50-C51)/B48 -> 0.72
A55: 2.5. Una società entra in un contratto futures lungo per acquistare 1.000 barili di petrolio a $60 per barile. Il margine iniziale è di $6.000 ed il margine di mantenimento è di $4.000.
A56: Quale prezzo futures del petrolio consentirà di prelevare $2.000 dal conto di deposito?
A57: (a) $58
A58: (b) $62
A59: (c) $64
A60: (d) $66
A62: (b)
A64: Dal deposito di garanzia può essere prelevato il denaro in eccesso rispetto al margine iniziale. L’aumento di $1 del prezzo futures comporta un guadagno di $1.000 (= 1.000 × $1). Pertanto, l’aumento di $2 comporta un guadagno di $2.000 che può essere prelevato dal conto.
A65: Il prezzo futures corrente è pari a $60. Ci sarà quindi la possibilità di prelevare $2.000 dal deposito di garanzia se il prezzo futures raggiunge i $62.
A67: Posizione | B67: 1
A68: Dimensione | B68: 1000
A69: F0 | B69: 60
A70: Margine iniziale | B70: 6000
A71: Margine di mantenimento | C71: 4000
A72: Prelievo | B72: 2000
A74: St | B74: =B69+B67*(B72/B68) -> 62
A76: 2.6. Sul floor di una borsa viene negoziato un contratto che serve ad entrambe le controparti per chiudere le posizioni in essere. Come si modifica l’open interest?
A77: (a) Non c’è nessuna variazione.
A78: (b) Scende di 1 unità.
A79: (c) Scende di due unità.
A80: (d) Aumenta di 1 unità.
...

Sheet 3
A1: Capitolo 3 Strategie di Copertura mediante Futures
A3: 3.1. La base è definita come differenza tra prezzo spot e prezzo futures. Considerate uno short hedger. La base si rafforza inaspettatamente. Quale delle seguenti affermazioni è corretta?
A4: (a) La posizione dell’hedger migliora.
A5: (b) La posizione dell’hedger peggiora.
A6: (c) La posizione dell’hedger a volte peggiora e a volte migliora.
A7: (d) La posizione dell’hedger né peggiora né migliora.
A9: (a)
A11: Il prezzo incassato dal trader dopo la copertura è pari al prezzo futures originario più la base. Ne segue che la posizione del trader migliora quando la base si rafforza.
A13: 3.2.Una società dovrà acquistare una certa attività il 15 giugno e desidera coprirsi. Su quale futures deve assumere una posizione lunga? Solo una delle seguenti risposte è corretta. Quale?
A14: (a) il futures per giugno;
A15: (b) il futures per luglio;
A16: (c) il futures per maggio;
... A34: Il costo post-copertura può anche essere calcolato come somma tra il prezzo futures del 1° marzo ($59) e la base del 1° giugno ($0,50)
A36: S0 | B36: 60
A37: F0 | B37: 59
A38: S1 | B38: 64
A39: F1 | B39: 63.5
A40: Posizione | B40: 1
A42: S1 − (F1 − F0) | C42: =B38-(B39-B37) -> 59.5
A43: F0 + b1 | B43: =B37+(B38-B39) -> 59.5
A45: 3.4. Il 1° marzo, una società che produce una certa merce entra in un contratto futures per dicembre, al fine di coprire una vendita che intende effettuare il 1° novembre. Il 1° novembre, la società chiude la posizione.
A46: Il 1° marzo, il prezzo spot della merce è di $1.000 e il prezzo futures per dicembre è di $1.015. Il 1° novembre, il prezzo spot della merce è di $980 e il prezzo futures per dicembre è di $981.
A47: Tenendo conto della copertura, qual è il ricavo effettivo per la società?
A48: (a) $1.016
A49: (b) $1.001
A50: (c) $981
A51: (d) $1.014
A53: (d)
A55: Per coprirsi, la società vende il futures a $1.015. Il guadagno sul futures è pari a $34 (= $1.015 − $981). Pertanto, il ricavo effettivo (tenendo conto della copertura) è pari a $1.014.
A56: Il ricavo post-copertura può anche essere calcolato come somma tra il prezzo futures del 1° marzo ($1.015) e la base del 1° novembre (−$1).
A58: S0 | B58: 1000
A59: F0 | B59: 1015
A60: S1 | B60: 980
A61: F1 | B61: 981
A62: Posizione | B62: -1
A64: S1 − (F1 − F0) | C64: =B60-(B61-B59) -> 1014
A65: F0 + b1 | B65: =B59+(B60-B61) -> 1014
A67: 3.5. La deviazione standard delle variazioni mensili del prezzo spot della merce A è pari a $2. La deviazione standard delle variazioni mensili del prezzo futures della merce B (simile alla merce A) è pari a $3.
A68: La correlazione tra il prezzo futures di B e il prezzo spot di A è pari a 0,9. Quale rapporto di copertura si dovrebbe utilizzare per coprire un’esposizione di un mese verso il prezzo spot della merce A?
A69: (a) 0,60
...

Sheet 4
A1: Capitolo 4 Tassi d’Interesse
A3: 4.1. La frequenza con cui un tasso d’interesse viene composto definisce
A4: (a) la frequenza con cui si pagano gli interessi;
A5: (b) l’unità di misura del tasso d’interesse;
A6: (c) la relazione tra il tasso d’interesse annuo e quello mensile;
A7: (d) nessuna delle precedenti risposte è corretta.
A9: (b)
A11: La frequenza con cui un tasso d’interesse viene composto è la sua unità di misura. La fre-quenza con cui si pagano gli interessi può essere diversa da quella con cui il tasso d’interes¬se viene composto.
A13: 4.2. Un tasso d’interesse composto annualmente è pari al 6 per cento annuo. Qual è il tasso equivalente composto continuamente?
A14: (a) 5,79%
A15: (b) 6,21%
A16: (c) 5,83%
... A21: Il tasso equivalente composto continuamente è pari al 5,83%.
A23: R | B23: 0.06
A24: m | B24: 1
A26: r | B26: =LN(1+B23) -> 0.058268908
A28: 4.3. Un tasso d’interesse composto continuamente è pari al 5 per cento annuo. Qual è il tasso equivalente composto semestralmente?
A29: (a) 5,06%
A30: (b) 5,03%
A31: (c) 4,97%
A32: (d) 4,94%
A34: (a)
A36: Il tasso equivalente composto semestralmente è pari al 5,06%.
A38: r | B38: 0.05
A39: m | B39: 2
A41: R | B41: =B39*(EXP(B38/B39)-1) -> 0.050630241
A43: 4.4. Un tasso d’interesse composto semestralmente è pari al 12% annuo. Qual è il tasso equivalente composto trimestralmente?
A44: (a) 11,83%
A45: (b) 11,66%
A46: (c) 11,77%
A47: (d) 11,92%
A49: (a)
A51: Il tasso equivalente composto trimestralmente è pari all’11,83%.
A53: R_m1 | B53: 0.12
A54: m1 | B54: 2
A55: m2 | B55: 4
A57: R_m2 | B57: =B55*((1+B53/B54)^(B54/B55)-1) -> 0.11825206
A59: 4.5. Lo zero rate a 2 anni è pari al 6% annuo e lo zero rate a 3 anni è pari al 6,5% annuo. Qual è il tasso forward per il 3° anno? Tutti i tassi sono composti continuamente.
A60: (a) 6,75%
A61: (b) 7,0%
...

Sheet 5
A1: Capitolo 5 Determinazione dei Prezzi Forward e dei Prezzi Futures
A3: 5.1. Solo una delle seguenti attività rappresenta un bene di consumo. Quale?
A4: (a) L’indice S&P 500.
A5: (b) Il dollaro canadese.
A6: (c) Il rame.
A7: (d) Le azioni IBM.
A9: (c)
A11: Le attività menzionate sub (a), (b) e (d) sono beni d’investimento, detenuti da alcuni soggetti solo per fini d’investimento. Invece, il rame, menzionato sub (c), è un bene di consumo.
A13: 5.2. Un investitore vende allo scoperto 100 azioni quando il prezzo è di $50 e chiude la posizione 6 mesi dopo quando il prezzo è di $43.
A14: Nel corso del semestre, le azioni pagano un dividendo unitario di $3. Qual è il profitto dell’investitore?
A15: (a) $1.000
A16: (b) $400
... A23: Pertanto, il profitto netto è pari a $4 (= $7 − $3) per azione. Dato che le azioni vendute allo scoperto sono 100, il profitto complessivo è pari a $400 (= $4 × 100)
A25: Posizione | B25: -1
A26: Dimensione | B26: 100
A27: S0 | B27: 50
A28: T | B28: 0.5
A29: ST | B29: 43
A30: d | B30: 3
A32: Profitto | B32: =B25*B26*(B29+B30-B27) -> 400
A34: 5.3. Il prezzo spot di un bene d’investimento che non offre redditi è di $30 e il tasso d’interesse privo di rischio per tutte le scadenze è del 10% (composto continuamente).
A35: Qual è il prezzo forward a 3 anni?
A36: (a) $40,50
A37: (b) $22,22
A38: (c) $33,00
A39: (d) $33,16
A41: (a)
A43: Il prezzo forward a 3 anni, che si ottiene capitalizzando il prezzo spot per tre anni al tasso d’interesse privo di rischio, è pari a $40,50
A45: S0 | B45: 30
A46: r | B46: 0.1
A47: T | B47: 3
A49: F0 | B49: =B45*EXP(B46*B47) -> 40.495764
A51: 5.4. Il prezzo spot di un bene d’investimento è di $30 e il tasso d’interesse privo di rischio per tutte le scadenze è del 10% (composto continuamente).
A52: Il bene d’investimento offre un reddito di $2 alla fine del primo e del secondo anno. Qual è il prezzo forward a 3 anni?
A53: (a) $19,67
A54: (b) $35,84
A55: (c) $45,15
A56: (d) $40,50
A58: (b)
A60: Il valore attuale del reddito è pari a $3,45 (= 2e−0.1×1 + 2e−0.1×2).
...

Sheet 6
A1: Capitolo 6 Futures su Tassi d’Interesse
A3: 6.1. Negli Stati Uniti, quale regola di calcolo giorni si applica ai corporate bonds?
A4: (a) Effettivi / 360.
A5: (b) Effettivi / effettivi.
A6: (c) 30 /360.
A7: (d) Effettivi /365.
A9: (c)
A11: Negli Stati Uniti, i corporate bonds vengono in genere quotati in base alla regola di calcolo giorni 30/360. In altri termini, quando si calcolano gli interessi maturati, si assume che ogni mese sia composto da 30 giorni e che ci siano quindi 360 giorni in un anno.
A13: 6.2. È il 1° maggio. Il prezzo quotato di un Treasury bond, con valore nominale di $100 e tasso cedolare del 12 per cento pagabile due volte l’anno (il 1° aprile e il 1° ottobre), è di $105.
A14: Qual è il prezzo effettivo?
A15: (a) $106,00
A16: (b) $106,02
... A23: In questo caso, il prezzo quotato è $105 e l’interesse maturato è pari a $0,98 (= 30 / 183 × 0,12 / 2 × $100). Pertanto, la risposta corretta è $105,98.
A25: T0 | B25: 38108
A26: Last coupon | B26: 38078
A27: Next coupon | B27: 38261
A28: L | B28: 100
A29: coupon rate | B29: 0.12
A30: m | B30: 2
A31: Clean price | B31: 105
A33: Prezzo effettivo | B33: =B31+B28*(B29/B30)*(B25-B26)/(B27-B26) -> 105.98361
A35: 6.3. È il 1° maggio. Il prezzo quotato di un corporate bond, con valore nominale di $100 e tasso cedolare del 12% pagabile due volte l’anno (il 1° aprile e il 1° ottobre), è di $105. Qual è il prezzo effettivo?
A36: (a) $106,00
A37: (b) $106,02
A38: (c) $105,98
A39: (d) $106,04
A41: (a)
A43: Il prezzo effettivo è pari al prezzo quotato più gli interessi maturati. Si assume che i giorni tra il 1° aprile e il 1° maggio siano 30 e quelli tra il 1° aprile e il 1° ottobre siano 180.
A44: In questo caso, il prezzo quotato è $105 e l’interesse maturato è pari a $1,00 (= 30 / 180 × 0,12 / 2 × $100). Pertanto, la risposta corretta è $106,00.
A46: T0 | B46: 38108
A47: Last coupon | B47: 38078
A48: Next coupon | B48: 38261
A49: L | B49: 100
A50: coupon rate | B50: 0.12
A51: m | B51: 2
A52: Clean price | B52: 105
A54: Prezzo effettivo | B54: =B52+B49*(B50/B51)*(DAYS360(B47,B46))/180 -> 106
A56: 6.4. Il prezzo quotato dei futures su Treasury bonds è di $103,5. Quale dei seguenti titoli è il cheapest to deliver?
A57: (a) | B57: Prezzo quotato: | C57: 110 | D57: fattore di conversione: | F57: 1.04
A58: (b) | B58: Prezzo quotato: | C58: 160 | D58: fattore di conversione: | F58: 1.52
...

Sheet 7
A1: Capitolo 7 Swaps
A3: 7.1. Una società può investire fondi per 5 anni al Sofr a 3 mesi – 30 p.b. Il tasso swap a 5 anni è pari al 3%. Se utilizza lo swap, qual è il tasso fisso che la società riesce a realizzare?
A4: (a) 2,4%
A5: (b) 2,7%
A6: (c) 3,0%
A7: (d) 3,3%
A9: (b)
A11: La società riceve il Sofr a 3 mesi – 30 p.b. ed entra in uno swap in cui paga il Sofr a 3 mesi e riceve il 3%. Il flusso netto annuo che riceve è pari al 2,7%:
A13: Rfl | B13: Sofr a 3 mesi | C13: =-30/10000 -> -0.003
A14: T | B14: 5
A15: Rswap | B15: 0.03
A17: Rfx | B17: =C13+B15 -> 0.027
A19: 7.2. Solo una delle seguenti affermazioni è corretta Quale?
A20: (a) Di solito, nei currency swaps non si scambiano i capitali.
A21: (b) Di solito, nei currency swaps i capitali viaggiano nella direzione opposta degli interessi all’inizio e nella stessa direzione degli interessi alla fine.
A22: (c) Di solito, nei currency swaps i capitali viaggiano nella stessa direzione degli interessi all’inizio e nella direzione opposta degli interessi alla fine.
A23: (d) Di solito, nei currency swaps non si specificano i capitali.
A25: (b)
A27: La risposta corretta è quella sub (b). Nei currency swaps sono presenti due capitali, uno per ogni valuta. I capitali viaggiano nella direzione opposta degli interessi all’inizio dello swap e nella stessa direzione degli interessi alla fine dello swap.
A29: 7.3. Considerate un interest rate swap, con decorrenza futura, in cui si scambia un tasso fisso con il Sofr a 3 mesi. Trascurando il rischio di credito, quale dei seguenti metodi di valutazione è appropriato?
A30: (a) Calcolare i pagamenti variabili in base ai corrispondenti Sofr a 3 mesi forward correnti e attualizzare i pagamenti netti in base agli OIS spot zero rates.
A31: (b) Calcolare tutti i pagamenti variabili utilizzando lo stesso Sofr a 3 mesi spot corrente e attua-lizzare i pagamenti netti in base agli OIS spot zero rates.
A32: (c) Calcolare i pagamenti variabili in base ai corrispondenti Sofr a 3 mesi forward correnti e attualizzare i pagamenti netti in base al tasso fisso contrattuale dello swap.
A33: (d) Calcolare tutti i pagamenti variabili utilizzando lo stesso Sofr a 3 mesi spot corrente e attua-lizzare i pagamenti netti in base al tasso fisso contrattuale dello swap.
... A172: Pertanto, il valore dello swap è pari a $2,66 (= $100 − $97,34), ossia al 2,66% del nozionale.
A174: Rswap | B174: 0.03
A175: L | B175: 100
A176: m | B176: 1
B177: t1 | C177: t2 | D177: t3
A178: Date | B178: 1 | C178: 2 | D178: 3
A179: Pagamenti | B179: =B174*B175 -> 3 | C179: =B174*B175 -> 3 | D179: =B175+B174*B175 -> 103
A180: Zero rates | B180: 0.02 | C180: 0.03 | D180: 0.04
A182: Val. attuale | B182: =B179/(1+B180)^B178*B176 -> 2.9411765 | C182: =C179/(1+C180)^C178*B176 -> 2.8277877 | D182: =D179/(1+D180)^D178*B176 -> 91.566625 | E182: =SUM(B182:D182) -> 97.335589
A183: Vswap | B183: =B175-E182 -> 2.6644109
A185: 7.16. Un interest rate swap, in cui si riceve il 5% (composto semestralmente) e si paga il Sofr a 6 mesi, ha 9 mesi di vita residua.
A186: I pagamenti vengono scambiati con frequenza semestrale. L’ultimo scambio è avvenuto 3 mesi fa e i prossimi avverranno tra 3 e 9 mesi.
A187: Il tasso annuo calcolato in base ai tassi Sofr giornalieri osservati negli ultimi 3 mesi è pari al 4,85% (composto continuamente).
A188: Gli OIS spot zero rates a 3 e a 9 mesi sono pari, rispettivamente, al 5,3% e al 5,8% annuo (entrambi composti continuamente).
A189: Se il capitale nozionale è pari a $15.000.000, qual è il valore dello swap per la parte che riceve il fisso? Trascurate il rischio di credito e le regole di calcolo giorni.
A190: (a) $74.250
...

Sheet 8
A1: Capitolo 8 Cartolarizzazioni e Crisi Finanziaria del 2007-8
A3: 8.1. Solo uno dei seguenti eventi tende a far aumentare il prezzo delle case. Quale?
A4: (a) L’aumento dei tassi d’interesse.
A5: (b) La fissazione di un tetto al loan-to-value ratio dei mutui da parte delle autorità di vigilanza.
A6: (c) La riduzione del livello minimo del FICO score richiesto dalle banche per la concessione dei mutui.
A7: (d) L’aumento dei pignoramenti immobiliari.
A9: (c)
A11: L’aumento dei tassi d’interesse tende a far diminuire i prezzi delle case perché i compratori devono sostenere costi di finanziamento più elevati.
A12: La fissazione di un tetto al «rapporto tra l’importo del mutuo e il valore di mercato della casa» (loan to value ratio) fa sì che alcuni possibili acquirenti non riescano a ottenere i mutui che desiderano. Di conseguenza, la minore domanda di case ha un effetto depressivo sui prezzi.
A13: L’aumento dei «pignoramenti immobiliari» (foreclosures) fa aumentare l’offerta di case e anche questo si traduce in una riduzione dei prezzi degli immobili.
A14: Invece, se le banche allentano i propri standard nella concessione dei mutui (ad es. riducendo livello minimo del FICO score) la domanda di case aumenta perché più gente può ottenere un mutuo. Di conseguenza, i prezzi aumentano.
A16: 8.2. Solo una delle seguenti affermazioni sui mutui «senza rivalsa» (non-recourse) è esatta. Quale?
... A49: L’equity tranche assorbe il 10% delle perdite. Il restante 6% (= 16% − 10%) viene assorbito dalla mezzanine tranche. La dimensione della mezzanine tranche è pari al 10%. Pertanto, le perdite per la mezzanine tranche dell’ABS sono pari al 60% (= 6% / 10%) del capitale.
A51: LS / L | B51: 0.8
A52: LM / L | B52: 0.1
A53: LE / L | B53: 0.1
A54: Perdite sul portafoglio di mutui subprime | C54: Perdite sull'equity tranche dell’ABS | E54: Perdite sulla mezz. tranche dell’ABS | G54: Perdite sulla senior tranche dell’ABS
A56: 0.16 | C56: =MIN(A56,B53)/B53 -> 1 | E56: =MAX(MIN(A56-B53,B52),0)/B52 -> 0.6 | G56: =MAX(MIN(A56-B53-B52,B51),0)/B51 -> 0
A58: 8.5. Supponete che vengano creati più ABSs sulla base di portafogli di mutui subprime.
A59: Le quote di capitale allocate alle singole tranches sono: senior 80%, mezzanine 10%, equity 10% (i portafogli di mutui subprime hanno gli stessi tassi d’insolvenza).
A60: Viene poi creata una ABS CDO sulla base delle mezzanine tranches dell’ABS.
A61: L’allocazione del capitale alle singole tranches dell’ABS CDO è uguale a quella degli ABSs.
A62: Ognuno dei portafogli di mutui subprime subisce perdite pari al 16% del capitale.
A63: In percentuale del capitale della tranche, quali sono le perdite per la mezzanine tranche dell’ABS CDO?
A64: (a) 50%
A65: (b) 60%
A66: (c) 80%
A67: (d) 100%
A69: (d)
A71: Come mostra la risposta alla precedente domanda, la mezzanine tranche dell’ABS viene «cancellata» (wiped out) per il 60%. Il primo 10% di questo 60% viene assorbito dall’equity tranche dell’ABS CDO.
A72: Il successivo 10% viene assorbito dalla mezzanine tranche dell’ABS CDO. Il restante 40% (= 60% − 10% − 10%) viene assorbito dalla senior tranche dell’ABS CDO. Pertanto, la mezzanine tranche dell’ABS CDO viene cancellata per il 100%:
A74: LS / L | C74: 0.8
A75: LM / L | C75: 0.1
A76: LE / L | C76: 0.1
A77: LABS CDO, S / LABS CDO | C77: 0.8
A78: LABS CDO, M / LABS CDO | C78: 0.1
A79: LABS CDO, E/ LABS CDO | C79: 0.1
A80: LABS CDO, S / L | C80: =C77*C75 -> 0.08
A81: LABS CDO, M / L | C81: =C78*C75 -> 0.01
A82: LABS CDO, E / L | C82: =C79*C75 -> 0.01
...

Sheet 9
A1: Capitolo 9 XVAs
A3: 9.1. Quale dei seguenti non è un aggiustamento di bilancio?
A4: (a) CVA.
A5: (b) MVA.
A6: (c) ZVA.
A7: (d) KVA.
A9: (c)
A11: CVA sta per credit value adjustment. MVA sta per margin valuation adjustment. KVA sta per capital valuation adjustment. ZVA non è un aggiustamento di bilancio.
A13: 9.2. CVA è l’acronimo di ...
A14: (a) collateral value adjustment;
A15: (b) credit value adjustment;
A16: (c) credit value agreement;
... A64: Il valore attuale delle perdite attese è pari a $450.000 (= $1.000.000 × 0,015 + $2.000.000 × 0,015). Questo è il CVA della banca.
A66: PV(EL1) | B66: 1000000
A67: PV(EL2) | B67: 2000000
A68: PD1 | B68: 0.015
A69: PD2 | B69: 0.015
A71: CVA | B71: =B66*B68+B67*B69 -> 45000
A73: 9.7. Una banca ha in essere, con una certa controparte, tre contratti non assistiti da garanzie. Il valore corrente dei tre contratti, per la banca, è pari a +$10, −$20 e +$25 milioni.
A74: Se è stata sottoscritta la clausola di netting, qual è la massima perdita che la banca può subire nel caso in cui la controparte fallisca oggi?
A75: (a) $15 milioni.
A76: (b) $35 milioni.
A77: (c) $20 milioni.
A78: (d) $0.
A80: (a)
A82: In base alla clausola di netting, i tre contratti vanno considerati alla stregua di un’unica transazione.
A83: Il valore netto dei tre contratti, per la banca, è pari a +$15 (= +$10 −$20 +$25) milioni. Questo è il massimo importo che la banca potrebbe perdere nel caso in cui la controparte fallisca oggi.
A84: V1 | B84: 10
A85: V2 | B85: -20
A86: V3 | B86: 25
A87: V | B87: =SUM(B84:B86) -> 15
A89: 9.8. Quale dei seguenti contratti comporta il maggior rischio di credito?
A90: (a) Un contratto negoziato in borsa.
A91: (b) Un contratto OTC con utilizzo di una central clearing party.
A92: (c) Un contratto OTC con bilateral clearing e collateral agreement.
A93: (d) Un contratto OTC con bilateral clearing, ma senza collateral agreement.
A95: (d)
A97: Nel caso dei contratti negoziati in borsa e in quelli OTC con utilizzo di una central clearing party, il meccanismo del marking to market fa sì che il rischio di credito sia molto basso. Il rischio è maggiore in caso di bilateral clearing, soprattutto quando non ci sono garanzie.
A99: 9.9. FVA è l’acronimo di un aggiustamento che riguarda ...
A100: (a) il costo del funding initial margin;
...

Sheet 10
A1: Capitolo 10 Funzionamento dei Mercati delle Opzioni
A3: 10.1. Solo una delle seguenti frasi descrive un’opzione call. Quale?
A4: (a) Il diritto di comprare una certa attività a un certo prezzo.
A5: (b) L’obbligo di comprare una certa attività a un certo prezzo.
A6: (c) Il diritto di vendere una certa attività a un certo prezzo.
A7: (d) L’obbligo di vendere una certa attività a un certo prezzo.
A9: (a)
A11: Le opzioni call danno al compratore il diritto, non l’obbligo, di comprare una certa attività a un certo prezzo.
A13: 10.2. Solo una delle seguenti affermazioni è corretta. Quale?
A14: (a) La long call equivale a una short put.
A15: (b) La short call equivale a una long put.
A16: (c) La call su un’azione più l’azione stessa equivale a una put.
... A32: Dopo un «frazionamento» (stock split), il numero delle azioni cresce e il prezzo d’esercizio diminuisce. In questo caso, dopo un frazionamento 2 × 1, il numero delle azioni raddoppia e il prezzo d’esercizio si dimezza.
A34: Nput | B34: 100
A35: K | B35: 20
A36: n1 | B36: 2
A37: m1 | B37: 1
A39: K | B39: Nput
A40: =B35*B37/B36 -> 10 | B40: =B34*B36/B37 -> 200
A42: 10.4. Considerate una put, negoziata in borsa, che dà a un investitore il diritto di vendere 100 azioni a $20 l’una. Qual è la posizione dell’investitore dopo uno stock dividend del 25%?
A43: (a) Ha una put che gli dà il diritto di vendere 100 azioni a $20 l’una.
A44: (b) Ha una put che gli dà il diritto di vendere 75 azioni a $25 l’una.
A45: (c) Ha una put che gli dà il diritto di vendere 125 azioni a $15 l’una.
A46: (d) Ha una put che gli dà il diritto di vendere 125 azioni a $16 l’una.
A48: (d)
A50: L’«assegnazione gratuita» (stock dividend) in misura pari al 25% delle azioni detenute equivale a un frazionamento 5 × 4. Il numero delle azioni cresce del 25% (125 = 100 × 5/4) e il prezzo d’esercizio si riduce a 4/5 del precedente valore ($16 = 4/5 × $20).
A52: Nput | B52: 100
A53: K | B53: 20
A54: n1 | B54: 5
A55: m1 | B55: 4
A57: K | B57: Nput
A58: =B53*B55/B54 -> 16 | B58: =B52*B54/B55 -> 125
A60: 10.5. Considerate una put, negoziata in borsa, che dà a un investitore il diritto di vendere 100 azioni a $20 l’una. Qual è la posizione dell’investitore dopo un dividendo di $1?
A61: (a) Ha una put che gli dà il diritto di vendere 100 azioni a $20 l’una.
A62: (b) Ha una put che gli dà il diritto di vendere 100 azioni a $19 l’una.
A63: (c) Ha una put che gli dà il diritto di vendere 105 azioni a $19 l’una.
A64: (d) Ha una put che gli dà il diritto di vendere 105 azioni a $19,05 l’una.
A66: (a)
A68: Le opzioni non sono protette contro lo stacco dei dividendi, a meno che i dividendi non siano di importo insolitamente elevato.
A70: 10.6. Solo una delle seguenti frasi descrive le posizioni corte su opzioni. Quale?
...

Sheet 11
A1: Capitolo 11 Proprietà Fondamentali delle Opzioni su Azioni
A3: 11.1. Quando il prezzo dell’azione sottostante aumenta, mentre tutto il resto rimane invariato, solo una delle seguenti affermazioni è corretta. Quale?
A4: (a) Il valore delle calls e delle puts aumenta.
A5: (b) Il valore delle calls e delle puts diminuisce.
A6: (c) Il valore delle calls aumenta, mentre il valore delle puts diminuisce.
A7: (d) Il valore delle calls diminuisce, mentre il valore delle puts aumenta.
A9: (c)
A11: Quando il prezzo dell’azione sottostante aumenta, il valore delle calls aumenta, mentre il valore delle puts diminuisce.
A13: 11.2. Quando il prezzo d’esercizio aumenta, mentre tutto il resto rimane invariato, solo una delle seguenti affermazioni è corretta. Quale?
A14: (a) Il valore delle calls e delle puts aumenta.
A15: (b) Il valore delle calls e delle puts diminuisce.
A16: (c) Il valore delle calls aumenta, mentre il valore delle puts diminuisce.
... A64: Di solito, quando la vita residua aumenta da X a Y, il valore delle opzioni europee aumenta. Tuttavia, non è sempre così. Se ci si aspetta che venga pagato un dividendo elevato tra X e Y, il valore delle calls europee potrebbe diminuire.
A65: 4
A66: 11.7. Qual è il limite inferiore per il prezzo di una call europea a 1 anno, scritta su un titolo che non paga dividendi, se il prezzo dell’azione sottostante è di $30, il prezzo d’esercizio è di $25
A67: e il tasso d’interesse privo di rischio (composto continuamente) è del 4 per cento annuo?
A68: (a) $5,00
A69: (b) $5,98
A70: (c) $4,98
A71: (d) $3,98
A73: (b)
A75: Il limite inferiore è pari a max(S0 − Ke−rT, 0). In questo caso è pari a $5,98.
A77: S0 | B77: 30
A78: K | B78: 25
A79: T | B79: 1
A80: r | B80: 0.04
A82: lim. inf. | B82: =MAX(B77-B78*EXP(-B80*B79),0) -> 5.980264
A84: 11.8. Qual è il limite inferiore per il prezzo di una put europea a 2 anni, scritta su un titolo che non paga dividendi, se il prezzo dell’azione sottostante è di $50, il prezzo d’esercizio è di $54
A85: e il tasso d’interesse privo di rischio (composto continuamente) è del 3 per cento annuo?
A86: (a) $4,00
A87: (b) $3,86
A88: (c) $2,86
A89: (d) $0,86
A91: (d)
A93: Il limite inferiore è pari a max(Ke−rT − S0, 0). In questo caso è pari a $0,86.
A95: S0 | B95: 50
A96: K | B96: 54
A97: T | B97: 2
A98: r | B98: 0.03
A100: lim. inf. | B100: =MAX(B96*EXP(-B98*B97)-B95,0) -> 0.85528481
...

Sheet 12
A1: Capitolo 12 Strategie Operative mediante Opzioni
A3: 12.1. Solo una delle seguenti frasi definisce un bull spread. Quale?
A4: (a) Comprare una call con strike basso e vendere una call con strike alto.
A5: (b) Comprare una call con strike alto e vendere una call con strike basso.
A6: (c) Comprare una call con strike basso e vendere una put con strike alto.
A7: (d) Comprare una put con strike basso e vendere una call con strike alto.
A9: (a)
A11: Il bull spread si ottiene comprando una call con strike basso e vendendo una call con strike alto. In alternativa, può essere ottenuto comprando una put con strike basso e vendendo una put con strike alto.
A13: 12.2. Solo una delle seguenti frasi definisce un bear spread. Quale?
A14: (a) Comprare una call con strike basso e vendere una call con strike alto.
A15: (b) Comprare una call con strike alto e vendere una call con strike basso.
A16: (c) Comprare una call con strike basso e vendere una put con strike alto.
... A173: Lo zero-coupon bond a 1 anno vale circa $951 (= $1.000 e−0,05×1). Per acquistare la call, restano quindi $49.
A175: r | B175: 0.05
A176: T | B176: 1
A177: L | B177: 1000
A179: c | B179: =B177*(1-EXP(-B175*B176)) -> 48.770575
A181: 12.18. Tre opzioni europee, con strikes $60, $65 e $70, costano $18, $14 e $11, rispettivamente.
A182: Per creare un butterfly spread lungo vengono utilizzate 400 calls. Tenendo conto del costo delle opzioni, qual è il massimo profitto netto che si può realizzare?
A183: (a) $100
A184: (b) $200
A185: (c) $300
A186: (d) $400
A188: (d)
A190: Il butterfly spread lungo richiede l’acquisto di 100 calls con strike $60, la vendita di 200 calls con strike $65 e l’acquisto di 100 calls con strike $70.
A191: Il massimo profitto viene realizzato quando il prezzo dell’azione è pari allo strike intermedio, che è pari a $65.
A192: In questo caso, i payoffs delle opzioni sono pari a $500 [= 100 × ($65 − $60)], $0 e $0, rispettivamente.
A193: Il payoff complessivo è quindi pari a $500. Il costo sostenuto per acquistare il butterfly spread lungo è pari a $100 (= 100 × $18 − 200 × $14 + 100 × $11).
A194: Pertanto, il massimo profitto netto che si può realizzare è pari a $400 (= $500 − $100).
B196: K
B197: 60 | C197: 65 | D197: 70
A198: c | B198: 18 | C198: 14 | D198: 11
A199: N | B199: 100 | C199: -200 | D199: 100
A200: ST | B200: =C197 -> 65
A202: Costo | B202: =B199*B198 -> 1800 | C202: =C199*C198 -> -2800 | D202: =D199*D198 -> 1100 | E202: =SUM(B202:D202) -> 100
A203: Payoff | B203: =B199*MAX($B$200-B197,0) -> 500 | C203: =C199*MAX($B$200-C197,0) -> 0 | D203: =D199*MAX($B$200-D197,0) -> 0 | E203: =SUM(B203:D203) -> 500
A204: Π | B204: =E203-E202 -> 400
A206: 12.19. Tre opzioni europee, con strikes $60, $65 e $70, costano $18, $14 e $11, rispettivamente.
A207: Per creare un butterfly spread lungo vengono utilizzate 400 calls. Tenendo conto del costo delle opzioni, qual è la massima perdita netta che si può subìre?
A208: (a) $100
...

Sheet 13
A1: Capitolo 13 Alberi Binomiali
A3: 13.1. Il prezzo corrente di un’azione è $30 e ci si aspetta che nei prossimi 6 mesi salga a $36 o scenda a $26.
A4: Il tasso d’interesse privo di rischio è nullo. Quale posizione sull’azione è necessaria per coprire una posizione corta su una call a 6 mesi con prezzo d’esercizio di $32?
A5: (a) Lunga su 0,6 azioni.
A6: (b) Lunga su 0,4 azioni.
A7: (c) Corta su 0,6 azioni.
A8: (d) Corta su 0,4 azioni.
A10: (b)
A12: Il valore della call a scadenza è pari a $4 [= max($36 − $32, $0)] in caso di rialzo o a $0 [= max($26 − $32, $0)] in caso di ribasso.
A13: Se Δ è la quantità di azioni da detenere, occorre che $36 Δ − $4 = $26 Δ − $0, da cui Δ = 0,4.
A14: Pertanto, occorre assumere una posizione lunga su 0,4 azioni.
A16: K | B16: 32
A17: T | B17: 0.5
A18: S0 | B18: 30
A19: u | B19: =36/B18 -> 1.2
A20: d | B20: =26/B18 -> 0.86666667
A21: r | B21: 0
A23: Δ | B23: =(MAX(B18*B19-B16,0)-MAX(B18*B20-B16,0))/(B18*B19-B18*B20) -> 0.4
A25: 13.2. Il prezzo corrente di un’azione è $30 e ci si aspetta che nei prossimi 6 mesi salga a $36 o scenda a $26.
A26: Il tasso d’interesse privo di rischio è nullo. Qual è la probabilità neutrale verso il rischio che il prezzo del titolo salga a $36?
A27: (a) 0,60
A28: (b) 0,50
A29: (c) 0,40
A30: (d) 0,30
A32: (c)
A34: La formula per calcolare la probabilità di rialzo, p, in un mondo neutrale verso il rischio, è:
A36: In questo caso si ha u = 1,2 (= $36 / $30) e d = 0,8667 (= $26 / $30). Inoltre, r = 0 e T = 0,5. Pertanto, in base alla formula, p = 0,40.
A38: K | B38: 32
A39: T | B39: 0.5
A40: S0 | B40: 30
A41: u | B41: =36/B40 -> 1.2
A42: d | B42: =26/B40 -> 0.86666667
A43: r | B43: 0
A45: p | B45: =(EXP(B43*B39)-B42)/(B41-B42) -> 0.4
A47: 13.3. Il prezzo corrente di un’azione è $30 e ci si aspetta che nei prossimi 6 mesi salga a $36 o scenda a $26.
A48: Il tasso d’interesse privo di rischio è nullo. Qual è il valore corrente di una call con prezzo d’esercizio di $32 e scadenza tra 6 mesi?
A49: (a) $1,6
A50: (b) $2,0
A51: (c) $2,4
A52: (d) $3,0
...

Sheet 14
A1: Capitolo 14 Processi di Wiener e Lemma di Itô
A3: 14.1. Una variabile, x, il cui livello corrente è 10, segue un processo di Wiener generalizzato dx = adt + bdz dove a = 2, b = 3 e il tempo è misurato in anni.
A4: Qual è il valore atteso di x tra 3 anni?
A5: (a) 12
A6: (b) 14
A7: (c) 16
A8: (d) 18
A10: (c)
A12: Il «tasso di deriva» (drift rate) annuo è pari a 2. Pertanto, l’incremento atteso in tre anni è pari a 6 (= 2 × 3) e il valore atteso di x tra 3 anni è pari a 16 (= 10 + 6).
A14: x | B14: 10
A15: a | B15: 2
A16: b | B16: 3
A17: T | B17: 3
A19: a T | B19: =B15*B17 -> 6
A20: E(x) | B20: =B14+B15*B17 -> 16
A22: 14.2. Una variabile, x, il cui livello corrente è 10, segue un processo di Wiener generalizzato dx = adt + bdz dove a = 3, b = 4 e il tempo è misurato in anni.
A23: Qual è la deviazione standard di x tra 4 anni?
A24: (a) 4
A25: (b) 8
A26: (c) 12
A27: (d) 16
A29: (b)
A31: Il «tasso di varianza» (variance rate) annuo è pari a 16 (= 42). Pertanto, la varianza di x tra 4 anni è pari a 64 (= 16 × 4) e la deviazione standard di x tra 4 anni è pari a 8 (= √64).
A33: x | B33: 10
A34: a | B34: 3
A35: b | B35: 4
A36: T | B36: 4
A38: b2 | B38: =B35^2 -> 16
A39: var(x) | B39: =B35^2*B36 -> 64
A40: std(x) | B40: =SQRT(B35^2*B36) -> 8
A42: 14.3. Una variabile, x, il cui livello corrente è 10, segue un processo di Wiener generalizzato dx = adt + bdz dove a = 3, b = 4 e il tempo è misurato in anni.
A43: Qual è la deviazione standard di x tra 3 mesi?
A44: (a) 1
A45: (b) 2
A46: (c) 3
A47: (d) 4
A49: (b)
A51: Il «tasso di varianza» (variance rate) annuo è pari a 16 (= 42). Pertanto, la varianza di x tra 4 anni è pari a 64 (= 16 × 4) e la deviazione standard di x tra 4 anni è pari a 8 (= √64).
A53: x | B53: 10
A54: a | B54: 3
...

Sheet 15
A1: Capitolo 15 Modello Black-Scholes-Merton
A3: 15.1. Considerate le ipotesi del modello Black-Scholes-Merton. Solo una delle seguenti affermazioni è corretta. Quale?
A4: (a) Il tasso di rendimento dell’azione nel prossimo istante di tempo si distribuisce in modo log-normale.
A5: (b) Il prezzo dell’azione in un futuro istante di tempo si distribuisce in modo log-normale.
A6: (c) Il prezzo dell’azione in un futuro istante di tempo si distribuisce in modo normale.
A7: (d) Nessuna delle precedenti risposte è corretta.
A9: (b)
A11: Il modello Black-Scholes-Merton assume che il tasso di rendimento di un’azione nel prossimo istante di tempo si distribuisca in modo normale. Questo implica che il prezzo dell’azione in un futuro istante di tempo si distribuisce in modo log-normale.
A13: 15.2. In quale anno sono stati pubblicati gli articoli «fondamentali» (path-breaking) di Black & Scholes e Merton?
A14: (a) 1983
A15: (b) 1984
A16: (c) 1974
... A42: La stima della deviazione standard della variazione del prezzo dell’azione nella prossima settimana è $2,77.
A44: S0 | B44: 100
A45: σ | B45: 0.2
A46: T | B46: =1/52 -> 0.019230769
A48: S σ √T | B48: =B44*B45*SQRT(B46) -> 2.773501
A50: 15.5. Nel modello Black-Scholes-Merton, N(d1) indica:
A51: (a) l’area della funzione di densità della normale standardizzata compresa tra 0 e d1.
A52: (b) l’area della funzione di densità della normale standardizzata compresa tra –∞ e d1.
A53: (c) l’area della funzione di densità della normale standardizzata compresa tra d1 e +∞.
A54: (d) l’area della funzione di densità della normale standardizzata compresa tra –d1 e d1.
A56: (b)
A58: Il campo di definizione di una variabile casuale normale va da −∞ a +∞. N(d1) indica l’area compresa tra −∞ e d1.
A60: 15.6. Se l’azione sottostante stacca un dividendo durante la vita di una call:
A61: (a) l’esercizio anticipato della call non è mai ottimale.
A62: (b) l’esercizio anticipato della call può essere ottimale un qualsiasi momento della sua vita;
A63: (c) l’esercizio anticipato della call può essere ottimale solo immediatamente dopo la data di stacco del dividendo.
A64: (d) Nessuna delle precedenti risposte è corretta.
... A129: Il valore atteso del tasso di rendimento a 1 anno (composto continuamente) è pari a μ − σ2/2. In questo caso, è pari all’8% (= 0,1 − 0,22/2).
A131: μ | B131: 0.1
A132: σ | B132: 0.2
A134: μ − σ2/2 | B134: =B131-B132^2/2 -> 0.08
A136: 15.13. Un investitore ha ottenuto i seguenti tassi di rendimento (composti annualmente) in 3 anni consecutivi: 2%, 12%, −10%. Qual è il tasso medio annuo equivalente (composto annualmente)?
A137: (a) 1,33%
A138: (b) 1,23%
A139: (c) 1,13%
A140: (d) 0,93%
A142: (d)
A144: Alla fine dei 3 anni un capitale iniziale di $100 sarebbe diventato pari a $102,816 (= $100 × 1,02 × 1,12 × 0,90). Il tasso medio annuo equivalente (composto annualmente) è lo 0,93%:
...

Sheet 16
A1: Capitolo 16 Stock Options per Impiegati e Dirigenti
A3: 16.1. Solo una delle seguenti affermazioni è corretta. Quale?
A4: (a) In genere, le stock options vengono detenute fino alla scadenza.
A5: (b) Le stock options tendono a essere esercitate prima delle corrispondenti opzioni negoziate in borsa o sul mercato OTC.
A6: (c) Le stock options tendono a essere esercitate più tardi delle corrispondenti opzioni negoziate in borsa o sul mercato OTC.
A7: (d) In genere, le stock options tendono a essere esercitate il prima possibile.
A9: (b)
A11: Le stock options tendono a essere esercitate prima delle corrispondenti opzioni negoziate in borsa o sul mercato OTC.
A12: Dato che non possono essere cedute a terzi, l’esercizio rappresenta l’unico modo per monetizzare il valore delle stock options. Le risposte sub (a), (c) e (d) non sono corrette.
A14: 16.2. Solo una delle seguenti affermazioni sulle stock options non è corretta. Quale?
A15: (a) È previsto un vesting period.
A16: (b) Possono essere cedute a altri dipendenti.
... A204: Le risposte (a), (b) e (c) spiegano i motivi della popolarità delle stock options nel settore delle start-ups.

Sheet 17
A1: Capitolo 17 Opzioni su Indici Azionari e Valute
A3: 17.1. Una società sa che riceverà valuta estera e vuole coprire la sua esposizione valutaria con un range forward. Cosa dovrebbe fare? Solo una delle seguenti affermazioni è corretta.
A4: (a) Comprare una put e vendere una call scritte sulla valuta estera. Il prezzo d’esercizio del-la put deve essere più elevato di quello della call.
A5: (b) Comprare una put e vendere una call scritte sulla valuta estera. Il prezzo d’esercizio della put deve essere più basso di quello della call.
A6: (c) Comprare una call e vendere una put scritte sulla valuta estera. Il prezzo d’esercizio della put deve essere più elevato di quello della call.
A7: (d) Comprare una call e vendere una put scritte sulla valuta estera. Il prezzo d’esercizio della put deve essere più basso di quello della call.
A9: (b)
A11: La società vuole che il prezzo che riceverà in cambio della valuta estera sia compreso tra K1 e K2 (K1 < K2). Pertanto, compra una put con strike K1 e vende una call con strike K2.
A13: 17.2. Una società sa che dovrà acquistare valuta estera e vuole coprire la sua esposizione valutaria con un range forward. Cosa dovrebbe fare? Solo una delle seguenti affermazioni è corretta.
A14: (a) Comprare una put e vendere una call scritte sulla valuta estera. Il prezzo d’esercizio della put deve essere più elevato di quello della call.
A15: (b) Comprare una put e vendere una call scritte sulla valuta estera. Il prezzo d’esercizio della put deve essere più basso di quello della call.
A16: (c) Comprare una call e vendere una put scritte sulla valuta estera. Il prezzo d’esercizio della put deve essere più elevato di quello della call.
... A54: Il gestore dovrebbe comprare 200 [= $10.000.000 / ($500 × 100)] contratti. I contratti vanno comprati, e non venduti, perché devono offrire un payoff positivo quando il mercato scende.
A56: VA | B56: 10000000
A57: T | B57: 0.5
A58: Lim. inf. | B58: 9500000
A59: S0 | B59: 500
A60: Size | B60: 100
A61: r | B61: 0.1
A62: qA | B62: 0
A63: qS | B63: 0
A64: β | B64: 1
A65: β* | B65: 0
A67: N | B67: =(B64-B65)*B56/(B60*B59) -> 200
A69: 17.6. Il gestore di un portafoglio azionario del valore di $10 milioni teme che il mercato possa rapidamente scendere nei prossimi 6 mesi
A70: e vuole utilizzare le opzioni su un indice azionario per assicurare il portafoglio contro la possibilità che scenda al di sotto dei $9,5 milioni.
A71: Il livello corrente dell’indice è di $500. Ogni contratto put è scritto su 100 volte il livello dell’indice. Se il beta del portafoglio è pari a 1, quale dovrebbe essere lo strike delle opzioni put?
A72: (a) $425
A73: (b) $450
A74: (c) $475
A75: (d) $500
A77: (c)
A79: Quando il valore del portafoglio scende del 5%, ci si attende che anche l’indice scenda del 5%. Pertanto, lo strike dovrebbe essere pari a $475 (= 0,95 × $500).
A81: VA | B81: 10000000
A82: T | B82: 0.5
A83: Lim. inf. | B83: 9500000
A84: S0 | B84: 500
A85: r | B85: 0.1
A86: β | B86: 1
A88: K | B88: =B84*(1+(B83/B81-1-(1-B86)*B85*B82)/B86) -> 475
...

Sheet 18
A1: Capitolo 18 Opzioni su Futures e Modello di Black
A3: 18.1. Quale posizione assume chi esercita una put scritta su un contratto futures? Una sola delle seguenti affermazioni è esatta:
A4: (a) Una posizione lunga sul contratto futures.
A5: (b) Una posizione corta sul contratto futures.
A6: (c) Una posizione lunga sull’attività sottostante il contratto futures.
A7: (d) Nessuna delle precedenti risposte è corretta.
A9: (b)
A11: Chi esercita una futures put assume una posizione corta sul contratto futures. La posizione può essere immediatamente chiusa senza costi aggiuntivi.
A13: 18.2. Quale posizione assume chi esercita una call scritta su un contratto futures? Una sola delle seguenti affermazioni è esatta:
A14: (a) Una posizione lunga sul contratto futures.
A15: (b) Una posizione corta sul contratto futures.
A16: (c) Una posizione lunga sull’attività sottostante il contratto futures.
... A73: La probabilità di rialzo è pari a (1 − d)/(u − d). In questo caso, u = 1,1 (= ¢44 / ¢40) e d = 0,85 (= ¢34 / ¢40). Pertanto, la probabilità di rialzo è pari a 0,6.
A75: F0 | B75: 40
A76: F0 u | B76: 44
A77: F0 d | B77: 34
A78: r | B78: 0.06
A80: u | B80: =B76/B75 -> 1.1
A81: d | B81: =B77/B75 -> 0.85
A82: p | B82: =(1-B81)/(B80-B81) -> 0.6
A84: 18.8. Il prezzo futures corrente di una certa attività è di ¢40. Ci si aspetta che nei prossimi 6 mesi salga a ¢44 o scenda a ¢34.
A85: I tassi d’interesse privi di rischio sono al livello del 6 per cento. Qual è il valore di una put, con prezzo d’esercizio di ¢37 e scadenza tra 6 mesi, scritta sul futures?
A86: (a) ¢3,00
A87: (b) ¢2,91
A88: (c) ¢1,16
A89: (d) ¢1,20
A91: (c)
A93: La probabilità di rialzo è pari a (1 − d)/(u − d). In questo caso, u = 1,1 (= ¢44 / ¢40) e d = 0,85 (= ¢34 / ¢40). Pertanto, la probabilità di rialzo è pari a 0,6. La futures put paga ¢0 in caso di rialzo e ¢3 (= ¢37 − ¢34) in caso di ribasso. Pertanto, il suo valore è pari a ¢1,16.
A95: F0 | B95: 40
A96: F0 u | B96: 44
A97: F0 d | B97: 34
A98: r | B98: 0.06
A99: K | B99: 37
A100: T | B100: 0.5
A102: u | B102: =B96/B95 -> 1.1
A103: d | B103: =B97/B95 -> 0.85
A104: p | B104: =(1-B103)/(B102-B103) -> 0.6
A105: put | B105: =EXP(-B98*B100)*(MAX(B99-B95*B102,0)*B104+MAX(B99-B95*B103,0)*(1-B104)) -> 1.1645346
A107: 18.9. Il prezzo futures corrente di una certa attività è di ¢40. Ci si aspetta che nei prossimi 6 mesi salga a ¢44 o scenda a ¢34.
A108: I tassi d’interesse privi di rischio sono al livello del 6 per cento. Qual è il valore di una call, con prezzo d’esercizio di ¢39 e scadenza tra 6 mesi, scritta sul futures?
...

Sheet 19
A1: Capitolo 19 Lettere Greche
A3: 19.1. Il delta di una call è 0,3. Un trader ne ha vendute 1.000 e vuole che il suo portafoglio sia neutrale in termini di delta. Cosa dovrebbe fare?
A4: (a) Vendere 300 azioni.
A5: (b) Comprare 300 azioni.
A6: (c) Vendere 700 azioni.
A7: (d) Comprare 700 azioni.
A9: (b)
A11: Quando il prezzo dell’azione aumenta in misura pari a un piccolo importo, il prezzo della call aumenta in misura pari al 30% di tale importo. Dato che ha venduto 1.000 calls, il trader è immunizzato dalle variazioni di prezzo dell’azione se compra 300 azioni.
A12: In tal modo, il delta del portafoglio passa da −300 [= 0,3 × (−1.000)] a 0 [= 0,3 × (−1.000) + 1 × (+300)].
A14: Δc | B14: 0.3
A15: Nc | B15: -1000
A17: NS | B17: =-B14*B15 -> 300
A19: 19.2. Cos’è il theta?
A20: (a) Il theta è la derivata del delta rispetto al prezzo del sottostante.
A21: (b) Il theta è la derivata del valore del portafoglio rispetto al tempo.
A22: (c) Il theta è la derivata del valore del portafoglio rispetto al tasso d’interesse.
A23: (d) Nessuna delle precedenti risposte è corretta.
A25: (b)
A27: Il theta è la derivata del valore del portafoglio rispetto al tempo.
A29: 19.3. Cos’è il gamma?
A30: (a) Il gamma è la derivata del delta rispetto al prezzo del sottostante.
A31: (b) Il gamma è la derivata del valore del portafoglio rispetto al tempo.
A32: (c) Il gamma è la derivata del valore del portafoglio rispetto al tasso d’interesse.
A33: (d) Nessuna delle precedenti risposte è corretta.
... A76: (a)
A78: Delta | B78: 2400
A79: Gamma | B79: -10
A80: opz_delta | B80: 0.5
A81: opz_gamma | B81: 0.04
A83: lunga su | B83: =-B79/B81 -> 250 | C83: opzioni
A85: 19.8. Un trader segue una strategia stop loss per coprire una posizione corta su una call, con prezzo d’esercizio di $0,7000 e scadenza tra 3 mesi, scritta su un tasso di cambio.
A86: Il trader copre l’opzione quando il tasso di cambio è di $0,7005 e chiude la copertura, tornando a una posizione scoperta, quando il tasso di cambio è di $0,6995. Il valore dell’opzione è di $0,1. Solo una delle seguenti affermazioni non è corretta. Quale?
A87: (a) Il costo delle compravendite può risultare nullo, per cui il trader guadagna $0,1 per ogni call venduta.
A88: (b) Il costo delle compravendite può risultare sensibilmente maggiore di $0,1 per ogni call venduta, per cui il trader chiude l’operazione in perdita.
A89: (c) Il valore attuale dei profitti e delle perdite sulle compravendite dovrebbe essere all’incirca pari – in media – a $0,1 per ogni call venduta.
A90: (d) La copertura funziona ragionevolmente bene.
A92: (d)
A94: Le coperture funzionano ragionevolmente bene se il loro costo è sempre vicino al valore teorico delle opzioni.
A95: La strategia stop loss non gode di questa proprietà. Il suo costo può essere nullo o molto superiore al valore teorico dell’opzione.
A96: In media, il costo della copertura non si discosta molto dal valore Black-Scholes-Merton dell’opzione, ma gli scostamenti dalla media possono essere piuttosto ampi.
...

Sheet 20
A1: Capitolo 20 Volatility Smiles e Volatility Surfaces
A3: 20.1. Solo una delle seguenti affermazioni sui grafici che illustrano i volatility smiles è corretta. Quale?
A4: (a) Sull’asse orizzontale c’è la volatilità implicita e sull’asse verticale il prezzo d’esercizio.
A5: (b) Sull’asse orizzontale c’è la volatilità storica e sull’asse verticale il prezzo d’esercizio.
A6: (c) Sull’asse orizzontale c’è il prezzo d’esercizio e sull’asse verticale la volatilità implicita.
A7: (d) Sull’asse orizzontale c’è il prezzo d’esercizio e sull’asse verticale la volatilità storica.
A9: (c)
A11: I volatility smiles mostrano la volatilità implicita (che è sull’asse verticale) in funzione del prezzo d’esercizio (che è sull’asse orizzontale).
A13: 20.2. Una sola delle seguenti affermazioni è esatta. Quale?
A14: (a) Il volatility smile per le puts europee è uguale al volatility smile per le calls europee.
A15: (b) Il volatility smile per le puts europee è uguale al volatility smile per le puts americane.
A16: (c) Il volatility smile per le calls europee è uguale al volatility smile per le calls americane.
... A158: La tavola riportata nel testo suggerisce una frequenza pari allo 0,03%, ossia 3/10.000. Dato che i giorni lavorativi in un anno sono 252, un evento a 6 deviazioni standard si verifica 1 volta ogni 13 [= 1/(0,03% × 252) anni.
A160: prob | B160: 0.0003
A161: n | B161: 252
A163: Anni | B163: =1/(B160*B161) -> 13.227513
A165: 20.16. Confrontate i tassi di variazione logaritmici dei tassi di cambio giornalieri con quelli di una variabile casuale normale che ha uguale media e uguale varianza. Solo una delle seguenti affermazioni è corretta. Quale?
A166: (a) Ai tassi di variazione piccoli e grandi, ma non a quelli intermedi, sono associate probabilità più elevate rispetto a quelle della corrispondente distribuzione normale.
A167: (b) I tassi di variazione piccoli sono meno probabili e quelli grandi sono più probabili dei tassi di variazione della corrispondente variabile casuale normale.
A168: (c) I tassi di variazione grandi sono meno probabili e quelli piccoli sono più probabili dei tassi di variazione della corrispondente variabile casuale normale.
A169: (d) Ai tassi di variazione piccoli e grandi, ma non a quelli intermedi, sono associate probabilità meno elevate rispetto a quelle della corrispondente distribuzione normale.
A171: (a)
A173: I tassi di variazione piccoli e grandi si verificano con frequenza maggiore rispetto a quelli della corrispondente variabile casuale normale.
A175: 20.17. Cosa succede quando la vita residua delle opzioni su valute aumenta? Solo una delle seguenti affermazioni è corretta. Quale?
A176: (a) Il volatility smile tende a diventare più pronunciato.
A177: (b) Il volatility smile tende a diventare meno pronunciato.
A178: (c) Il volatility smile tende a diventare dapprima meno pronunciato e poi più pronunciato.
A179: (d) Il volatility smile resta più o meno invariato.
... A224: Poi interpoliamo tra le scadenze. La volatilità implicita in un’opzione a 10 mesi con strike $1,12 è pari al 19,52%:
C226: 6 | D226: 12 | F226: 10
A227: Surface | B227: 1.1 | C227: 0.2 | D227: 0.188 | F227: =C227+(F226-C226)/(D226-C226)*(D227-C227) -> 0.192
B228: 1.2 | C228: 0.22 | D228: 0.202 | F228: =C228+(F226-C226)/(D226-C226)*(D228-C228) -> 0.208
B230: 1.12 | C230: =C227+(B230-B227)/(B228-B227)*(C228-C227) -> 0.204 | D230: =D227+(B230-B227)/(B228-B227)*(D228-D227) -> 0.1908 | F230: =C230+(F226-C226)/(D226-C226)*(D230-C230) -> 0.1952 | G230: =F227+(B230-B227)/(B228-B227)*(F228-F227) -> 0.1952

Sheet 21
A1: Capitolo 21 Procedure Numeriche
A3: 21.1. Quanti nodi ci sono alla fine di un albero binomiale a 5 stadi, costruito secondo Cox-Ross-Rubinstein?
A4: (a) 4
A5: (b) 5
A6: (c) 6
A7: (d) 7
A9: (c)
A11: Il numero dei nodi finali in un albero binomiale a n stadi è pari a n + 1. Pertanto, la risposta corretta per un albero a n = 5 stadi, è 6 (= 5 + 1).
A13: n | B13: 5
A15: Nodi finali | B15: =B13+1 -> 6
A17: 21.2. Solo una delle seguenti lettere greche non può essere calcolata in base a un unico albero binomiale. Quale?
A18: (a) delta
A19: (b) gamma
A20: (c) theta
A21: (d) vega
A23: (d)
A25: Per calcolare il vega occorre aumentare leggermente la volatilità e costruire un nuovo albero. Le altre tre greche possono essere calcolate in base a un unico albero.
A27: 21.3. Considerate il parametro u nell’albero binomiale di Cox-Ross-Rubinstein. Solo una delle seguenti affermazioni è corretta. Quale?
A28: (a) Dipende dal tasso d’interesse e dalla volatilità.
A29: (b) Dipende dalla volatilità, ma non dal tasso d’interesse.
A30: (c) Dipende dal tasso d’interesse, ma non dalla volatilità.
A31: (d) Non dipende né dal tasso d’interesse né dalla volatilità.
... A97: In base alla tecnica della variabile di controllo, il valore dell’opzione americana è pari $3,06.
A99: Cbin | B99: 3.12
A100: cbin | B100: 3.04
A101: cbsm | B101: 2.98
A103: Cvc | B103: =B99+B101-B100 -> 3.06
A105: 21.10. Nel capitolo viene presentato un metodo di costruzione degli alberi binomiali alternativo a quello di Cox-Ross-Rubinstein (CRR). In questa alternativa, quale delle seguenti affermazioni è corretta?
A106: (a) La relazione tra u e d è u = 1/d.
A107: (b) La relazione tra u e d è u − 1 = 1 − d.
A108: (c) Le probabilità presenti nell’albero sono tutte uguali a 0,5.
A109: (d) Nessuna delle precedenti risposte è corretta.
A111: (c)
A113: Invece di utilizzare un grado di libertà per porre u = 1/d (come in CRR), il metodo alternativo utilizza un grado di libertà per fissare in 0,5 le probabilità di rialzo e di ribasso.
A115: 21.11. Solo una delle seguenti tipologie di opzioni non può essere valutata facilmente con il metodo Monte Carlo. Quale?
A116: (a) Le opzioni europee.
A117: (b) Le opzioni americane.
A118: (c) Le opzioni asiatiche, ossia le opzioni sul prezzo medio.
A119: (d) Le opzioni che pagano $100 se il prezzo dell’azione a scadenza è maggiore dello strike.
... A155: L’errore standard della stima è ω/√M. Nel nostro caso, l’errore standard della stima è pari a $0,045 (= $4,5/√10.000).
...

Sheet 22
A1: Capitolo 22 Valore a Rischio ed Expected Shortfall
A3: 22.1. Considerate il VaR al 99,9%. Quale delle seguenti affermazioni è corretta?
A4: (a) C’è 1 probabilità su 10 che la perdita sia maggiore del VaR.
A5: (b) C’è 1 probabilità su 100 che la perdita sia maggiore del VaR.
A6: (c) C’è 1 probabilità su 1.000 che la perdita sia maggiore del VaR.
A7: (d) Nessuna delle precedenti affermazioni è corretta.
A9: (c)
A11: Se il VaR è al 99,9%, c’è una probabilità pari allo 0,1% (= 100% − 99,9%) che la perdita ecceda il VaR. Lo 0,1% è pari 1 su 1.000.
A13: 22.2. I profitti di un progetto d’investimento si distribuiscono in modo uniforme tra –$0,15 milioni e +$0,85 milioni. Qual è il VaR al 99%?
A14: (a) $0,145 milioni
A15: (b) $0,14 milioni
A16: (c) $0,13 milioni
... A22: Pertanto, c’è una probabilità del 99% che la perdita non sarà maggiore di $0,14 milioni. Questo è il VaR al 99%.
A24: a | B24: -0.15
A25: b | B25: 0.85
A26: α | B26: 0.99
A28: VaR | B28: =-(B25-B26*(B25-B24)) -> 0.14
A30: 22.3. I profitti di un progetto d’investimento si distribuiscono in modo uniforme tra –$0,15 milioni e +$0,85 milioni. Qual è l'Expected shortfall al 99%?
A31: (a) $0,145 milioni
A32: (b) $0,14 milioni
A33: (c) $0,13 milioni
A34: (d) $0,10 milioni
A36: (a)
A38: Come si è visto nella risposta al test precedente, il VaR al 99% è pari a $0,14 milioni. Se la perdita è maggiore di $0,14 milioni, è ugualmente probabile che sia compresa tra $0,14 e $0,15 milioni.
A39: Pertanto, il valore atteso della perdita, condizionato dal fatto che la perdita sia maggiore di $0,14 milioni, è pari a $0,145 milioni. Questa è l’expected shortfall al 99%.
A41: a | B41: -0.15
A42: b | B42: 0.85
A43: α | B43: 0.99
A45: VaR | B45: =-(B42-B43*(B42-B41)) -> 0.14
A46: Shortfall | B46: =AVERAGE(B45,-B41) -> 0.145
A48: 22.4. Considerate il metodo delle simulazioni storiche per il calcolo del VaR. Solo una delle seguenti affermazioni è corretta. Quale?
A49: (a) Il metodo delle simulazioni storiche consente di stimare una distribuzione normale sulla base dei dati storici di alcune variabili.
A50: (b) Il metodo delle simulazioni storiche consente di stimare una distribuzione log-normale sulla base dei dati storici di alcune variabili.
A51: (c) Il metodo delle simulazioni storiche assume che il futuro sia un campione casuale estratto dal quel che è successo in passato.
A52: (d) Il metodo delle simulazioni storiche utilizza le simulazioni Monte Carlo per generare futuri scenari probabilistici.
A54: (c)
A56: Il metodo delle simulazioni storiche assume che i tassi di variazione delle variabili di mercato che verranno osservati domani rappresentino un campione casuale estratto dalla distribuzione dei tassi di variazione osservati storicamente in un certo numero di giorni.
A58: 22.5. Spesso si assume che il VaR a 10 giorni sia equivalente a:
A59: (a) il VaR a 1 giorno moltiplicato per 10;
A60: (b) il VaR a 1 giorno moltiplicato per √10;
...

Sheet 23
A1: Capitolo 23 Stima di Volatilità e Correlazioni
A3: 23.1. Quanti parametri sono necessari per definire il modello EWMA?
A4: (a) 1
A5: (b) 2
A6: (c) 3
A7: (d) 4
A9: (a)
A11: Per definire il modello EWMA è necessario un solo parametro.
A13: 23.2. Quanti parametri sono necessari per definire il modello GARCH(1, 1)?
A14: (a) 1
A15: (b) 2
A16: (c) 3
... A31: Alla fine di venerdì, la varianza del tasso di rendimento giornaliero di A è pari a 0,00045 [= 0,9 × 0,022 + (1 − 0,9) × 0,032]. Pertanto, la volatilità è pari al 2,12%.
A33: σt | B33: 0.02
A34: ut | B34: 0.03
A35: lambda | B35: 0.9
A37: σ2t+1 | B37: =B35*B33^2+(1-B35)*B34^2 -> 0.00045
A38: σt+1 | B38: =SQRT(B37) -> 0.021213203
A40: 23.4. Alla fine di giovedì, la volatilità giornaliera del titolo B è pari all’1%. Venerdì, il tasso di rendimento giornaliero di B è pari allo 0%. Utilizzate il modello EWMA con λ = 0,9. Qual è la stima della volatilità di B alla fine di venerdì?
A41: (a) 0,98%
A42: (b) 0,95%
A43: (c) 0,92%
A44: (d) 0,90%
A46: (b)
A48: Alla fine di venerdì, la varianza del tasso di rendimento giornaliero di B è pari a 0,00009 [= 0,9 × 0,012 + (1 − 0,9) × 0,002]. Pertanto, la volatilità è pari all0 0,95%.
A50: σt | B50: 0.01
A51: ut | B51: 0
A52: lambda | B52: 0.9
A54: σ2t+1 | B54: =B52*B50^2+(1-B52)*B51^2 -> 9e-05
A55: σt+1 | B55: =SQRT(B54) -> 0.009486833
A57: 23.5. Alla fine di giovedì, la covarianza tra i tassi di rendimento dei titoli A e B è di 0,0001.
A58: Venerdì, i tassi di rendimento giornalieri di A e B sono pari, rispettivamente, al 3% e allo 0%. Utilizzate il modello EWMA con λ = 0,9. Qual è la stima della covarianza tra i tassi di rendimento dei due titoli alla fine di venerdì?
A59: (a) 0,000090
A60: (b) 0,000081
A61: (c) 0,000100
A62: (d) 0,000095
A64: (a)
A66: Alla fine di venerdì, la covarianza tra i tassi di rendimento di A e B è pari a 0,000090.
A68: σA, B | B68: 0.0001
A69: uA | B69: 0.03
...

Sheet 24
A1: Capitolo 24 Rischio di Credito
A3: 24.1. Supponiamo che le probabilità d’insolvenza di una certa società a 1, 2, 3 e 4 anni siano pari, rispettivamente, al 3,0%, 6,5%, 10,0% e 14,5%.
A4: Qual è la probabilità d’insolvenza relativa al 4° anno condizionata dalla non insolvenza negli anni precedenti?
A5: (a) 4,5%
A6: (b) 5,0%
A7: (c) 5,5%
A8: (d) 6,0%
A10: (b)
A12: La probabilità d’insolvenza, non condizionata, relativa al 4° anno è pari al 4,5%.
A13: La probabilità che la società non risulti insolvente nei primi 3 anni è pari al 90% (= 100% − 10%). Pertanto, la probabilità d’insolvenza nel 4° anno, condizionata dalla non insolvenza negli anni precedenti, è pari al 5%.
